<robot name="single_leg" version="1.0">
  <joint name="joint1" type="revolute">
    <limit lower="-3.14000" upper="3.14000" effort="0.00000" velocity="0.00000"/>
    <origin rpy="-1.57080 0.00000 0.00000" xyz="0.04100 0.01800 -0.00000"/>
    <parent link="link0_link"/>
    <child link="link1_link"/>
    <axis xyz="0.00000 0.00000 1.00000"/>
  </joint>
  <joint name="joint2" type="revolute">
    <limit lower="-3.14000" upper="3.14000" effort="0.00000" velocity="0.00000"/>
    <origin rpy="-0.00000 0.00000 0.00000" xyz="0.00001 0.07999 0.00825"/>
    <parent link="link1_link"/>
    <child link="link2_link"/>
    <axis xyz="0.00000 0.00000 1.00000"/>
  </joint>
  <joint name="joint3" type="revolute">
    <limit lower="-3.14000" upper="3.14000" effort="0.00000" velocity="0.00000"/>
    <origin rpy="-0.00000 0.00000 0.00000" xyz="-0.12919 0.01447 -0.00000"/>
    <parent link="link2_link"/>
    <child link="link3_link"/>
    <axis xyz="0.00000 0.00000 1.00000"/>
  </joint>
  <joint name="joint4" type="revolute">
    <limit lower="-3.14000" upper="3.14000" effort="0.00000" velocity="0.00000"/>
    <origin rpy="-0.00000 0.00000 0.00000" xyz="-0.03281 -0.09447 -0.00000"/>
    <parent link="link3_link"/>
    <child link="link4_link"/>
    <axis xyz="0.00000 0.00000 1.00000"/>
  </joint>
  <joint name="joint5" type="revolute">
    <limit lower="-3.14000" upper="3.14000" effort="0.00000" velocity="0.00000"/>
    <origin rpy="-1.57080 0.00000 0.00000" xyz="-0.04100 0.01800 0.00003"/>
    <parent link="link0_link"/>
    <child link="link4_dummy_link"/>
    <axis xyz="0.00000 0.00000 1.00000"/>
  </joint>
  <link name="link0_link">
    <visual name="link0">
      <origin rpy="0.00000 0.00000 0.00000" xyz="0.00000 0.00000 0.00000"/>
      <geometry>
        <mesh filename="../meshes/stl/link0.stl" scale="1.00000 1.00000 1.00000"/>
      </geometry>
    </visual>
  </link>
  <link name="link1_link">
    <inertial>
      <inertia ixx="0.00007" ixy="-0.00000" ixz="-0.00000" iyy="0.00007" iyz="0.00000" izz="0.00000"/>
      <origin rpy="0.00000 0.00000 0.00000" xyz="0.00001 0.02888 0.00660"/>
      <mass value="0.10000"/>
    </inertial>
    <visual name="link1">
      <origin rpy="1.57080 0.00000 0.00000" xyz="0.00000 0.00000 0.00000"/>
      <geometry>
        <mesh filename="../meshes/stl/link - up_arm-8.stl" scale="1.00000 1.00000 1.00000"/>
      </geometry>
    </visual>
  </link>
  <link name="link2_link">
    <inertial>
      <inertia ixx="0.00000" ixy="0.00000" ixz="0.00002" iyy="0.00016" iyz="-0.00000" izz="0.00015"/>
      <origin rpy="0.00000 0.00000 0.00000" xyz="-0.06461 0.00732 -0.00000"/>
      <mass value="0.10000"/>
    </inertial>
    <visual name="link2">
      <origin rpy="1.57080 0.00000 0.00000" xyz="-0.00000 -0.00000 0.00000"/>
      <geometry>
        <mesh filename="../meshes/stl/link - low_arm_rear-3.stl" scale="1.00000 1.00000 1.00000"/>
      </geometry>
    </visual>
  </link>
  <link name="link3_link">
    <inertial>
      <inertia ixx="0.00036" ixy="-0.00001" ixz="-0.00012" iyy="0.00040" iyz="-0.00004" izz="0.00005"/>
      <origin rpy="0.00000 0.00000 0.00000" xyz="-0.00036 -0.00045 -0.00380"/>
      <mass value="0.10000"/>
    </inertial>
    <visual name="link3">
      <origin rpy="1.57080 0.00000 0.00000" xyz="-0.00000 0.00000 0.00000"/>
      <geometry>
        <mesh filename="../meshes/stl/link - touch_part-2.stl" scale="1.00000 1.00000 1.00000"/>
      </geometry>
    </visual>
  </link>
  <link name="link4_dummy_link">
    <visual name="link4_dummy">
      <origin rpy="1.57080 0.00000 0.00000" xyz="-0.07999 0.00001 0.00825"/>
      <geometry>
        <mesh filename="../meshes/stl/link - up_arm-5.001.stl" scale="1.00000 1.00000 1.00000"/>
      </geometry>
    </visual>
  </link>
  <link name="link4_link">
    <inertial>
      <inertia ixx="0.00000" ixy="-0.00000" ixz="0.00000" iyy="0.00007" iyz="-0.00000" izz="0.00007"/>
      <origin rpy="0.00000 0.00000 0.00000" xyz="0.07999 -0.00001 -0.00825"/>
      <mass value="0.10000"/>
    </inertial>
    <visual name="link4">
      <origin rpy="1.57080 0.00000 0.00000" xyz="0.00000 0.00000 -0.00000"/>
      <geometry>
        <mesh filename="../meshes/stl/link - up_arm-5.stl" scale="1.00000 1.00000 1.00000"/>
      </geometry>
    </visual>
  </link>
</robot>