<robot name="quadson" version="1.0">

  <!-- 
    Joints 
  -->

  <!-- Back Left -->
  <joint name="bl_joint0" type="revolute">
    <limit lower="-3.14000" upper="3.14000" effort="0.00000" velocity="0.00000"/>
    <origin rpy="-0.00000 1.57080 0.00000" xyz="-0.20768 0.09541 0.00215"/>
    <parent link="base_link_.002_link"/>
    <child link="link0.003"/>
    <axis xyz="0.00000 0.00000 1.00000"/>
  </joint>

  <joint name="bl_joint1" type="revolute">
    <limit lower="-3.14000" upper="3.14000" effort="0.00000" velocity="0.00000"/>
    <origin rpy="-1.57080 -1.57080 0.00000" xyz="0.00040 0.01862 0.05458"/>
    <parent link="link0.003"/>
    <child link="link1.003"/>
    <axis xyz="0.00000 0.00000 1.00000"/>
  </joint>

  <joint name="bl_joint2" type="revolute">
    <limit lower="-3.14000" upper="3.14000" effort="0.00000" velocity="0.00000"/>
    <origin rpy="-0.00000 -0.00000 -0.00000" xyz="-0.04179 0.06838 0.00778"/>
    <parent link="link1.003"/>
    <child link="link2.003"/>
    <axis xyz="0.00000 0.00000 1.00000"/>
  </joint>

  <joint name="bl_joint3" type="revolute">
    <limit lower="-3.14000" upper="3.14000" effort="0.00000" velocity="0.00000"/>
    <origin rpy="-0.00000 0.00000 -0.00000" xyz="0.05995 0.08004 -0.00055"/>
    <parent link="link2.003"/>
    <child link="link3.003"/>
    <axis xyz="0.00000 0.00000 1.00000"/>
  </joint>

  <joint name="bl_joint4" type="revolute">
    <limit lower="-3.14000" upper="3.14000" effort="0.00000" velocity="0.00000"/>
    <origin rpy="-0.00000 0.00000 0.00000" xyz="0.10334 -0.07887 0.00054"/>
    <parent link="link3.003"/>
    <child link="link4.004"/>
    <axis xyz="0.00000 0.00000 1.00000"/>
  </joint>

  <!-- Back Right -->
  <joint name="br_joint0" type="revolute">
    <limit lower="-3.14000" upper="3.14000" effort="0.00000" velocity="0.00000"/>
    <origin rpy="-0.00000 1.57080 0.00000" xyz="-0.20768 -0.09459 0.00215"/>
    <parent link="base_link_.002_link"/>
    <child link="link0.002"/>
    <axis xyz="0.00000 0.00000 1.00000"/>
  </joint>

  <joint name="br_joint1" type="revolute">
    <limit lower="-3.14000" upper="3.14000" effort="0.00000" velocity="0.00000"/>
    <origin rpy="1.57080 -1.57080 0.00000" xyz="0.00040 -0.01862 0.05458"/>
    <parent link="link0.002"/>
    <child link="link1.002"/>
    <axis xyz="0.00000 0.00000 1.00000"/>
  </joint>

  <joint name="br_joint2" type="revolute">
    <limit lower="-3.14000" upper="3.14000" effort="0.00000" velocity="0.00000"/>
    <origin rpy="0.00000 0.00000 -0.00000" xyz="-0.04173 -0.06842 0.00768"/>
    <parent link="link1.002"/>
    <child link="link2.002"/>
    <axis xyz="0.00000 0.00000 1.00000"/>
  </joint>

  <joint name="br_joint3" type="revolute">
    <limit lower="-3.14000" upper="3.14000" effort="0.00000" velocity="0.00000"/>
    <origin rpy="0.00000 0.00000 -0.00000" xyz="0.05988 -0.08000 -0.00045"/>
    <parent link="link2.002"/>
    <child link="link3.002"/>
    <axis xyz="0.00000 0.00000 1.00000"/>
  </joint>

  <joint name="br_joint4" type="revolute">
    <limit lower="-3.14000" upper="3.14000" effort="0.00000" velocity="0.00000"/>
    <origin rpy="0.00000 0.00000 -0.00000" xyz="0.10341 0.07891 0.00044"/>
    <parent link="link3.002"/>
    <child link="link4.001"/>
    <axis xyz="0.00000 0.00000 1.00000"/>
  </joint>

  <!-- Front Left -->
  <joint name="fl_jjoint1" type="revolute">
    <limit lower="-3.14000" upper="3.14000" effort="0.00000" velocity="0.00000"/>
    <origin rpy="-1.57080 1.57080 0.00000" xyz="-0.00040 0.01862 0.05430"/>
    <parent link="link0.004"/>
    <child link="link1.004"/>
    <axis xyz="0.00000 0.00000 1.00000"/>
  </joint>

  <joint name="fl_jjoint2" type="revolute">
    <limit lower="-3.14000" upper="3.14000" effort="0.00000" velocity="0.00000"/>
    <origin rpy="-0.00000 -0.00000 -0.00000" xyz="0.04173 0.06842 0.00768"/>
    <parent link="link1.004"/>
    <child link="link2.004"/>
    <axis xyz="0.00000 0.00000 1.00000"/>
  </joint>
  
  <joint name="fl_jjoint3" type="revolute">
    <limit lower="-3.14000" upper="3.14000" effort="0.00000" velocity="0.00000"/>
    <origin rpy="-0.00000 0.00000 -0.00000" xyz="-0.05988 0.08000 -0.00045"/>
    <parent link="link2.004"/>
    <child link="link3.004"/>
    <axis xyz="0.00000 0.00000 1.00000"/>
  </joint>

  <joint name="fl_jjoint4" type="revolute">
    <limit lower="-3.14000" upper="3.14000" effort="0.00000" velocity="0.00000"/>
    <origin rpy="-0.00000 -0.00000 0.00000" xyz="-0.10334 -0.07887 0.00054"/>
    <parent link="link3.004"/>
    <child link="link4.005"/>
    <axis xyz="0.00000 0.00000 1.00000"/>
  </joint>

  <joint name="fl_joint0" type="revolute">
    <limit lower="-3.14000" upper="3.14000" effort="0.00000" velocity="0.00000"/>
    <origin rpy="0.00000 -1.57080 0.00000" xyz="0.20740 0.09541 0.00215"/>
    <parent link="base_link_.002_link"/>
    <child link="link0.004"/>
    <axis xyz="0.00000 0.00000 1.00000"/>
  </joint>

  <!-- Front Right -->
  <joint name="fr_joint0" type="revolute">
    <limit lower="-3.14000" upper="3.14000" effort="0.00000" velocity="0.00000"/>
    <origin rpy="0.00000 -1.57080 0.00000" xyz="0.20740 -0.09459 0.00215"/>
    <parent link="base_link_.002_link"/>
    <child link="fr_link0.002"/>
    <axis xyz="0.00000 0.00000 1.00000"/>
  </joint>

  <joint name="fr_joint1" type="revolute">
    <limit lower="-3.14000" upper="3.14000" effort="0.00000" velocity="0.00000"/>
    <origin rpy="1.57080 1.57080 0.00000" xyz="0.00039 -0.01915 0.05430"/>
    <parent link="fr_link0.002"/>
    <child link="fr_llink1.002"/>
    <axis xyz="0.00000 0.00000 1.00000"/>
  </joint>

  <joint name="fr_joint2" type="revolute">
    <limit lower="-3.14000" upper="3.14000" effort="0.00000" velocity="0.00000"/>
    <origin rpy="0.00000 0.00000 0.00000" xyz="0.04179 -0.06838 0.00778"/>
    <parent link="fr_llink1.002"/>
    <child link="fr_llink2.002"/>
    <axis xyz="0.00000 0.00000 1.00000"/>
  </joint>

  <joint name="fr_joint3" type="revolute">
    <limit lower="-3.14000" upper="3.14000" effort="0.00000" velocity="0.00000"/>
    <origin rpy="0.00000 0.00000 0.00000" xyz="-0.05995 -0.08004 -0.00055"/>
    <parent link="fr_llink2.002"/>
    <child link="fr_llink3.002"/>
    <axis xyz="0.00000 0.00000 1.00000"/>
  </joint>

  <joint name="fr_joint4" type="revolute">
    <limit lower="-3.14000" upper="3.14000" effort="0.00000" velocity="0.00000"/>
    <origin rpy="0.00000 0.00000 0.00000" xyz="-0.10341 0.07891 0.00044"/>
    <parent link="fr_llink3.002"/>
    <child link="fr_llink4.002"/>
    <axis xyz="0.00000 0.00000 1.00000"/>
  </joint>

  <!-- 
    Links 
  -->

  <!-- Base Link -->
  <link name="base_link_.002_link">
    <inertial>
      <inertia ixx="0.00472" ixy="0.00000" ixz="0.00000" iyy="0.02855" iyz="-0.00000" izz="0.02916"/>
      <origin rpy="0.00000 0.00000 0.00000" xyz="-0.00001 0.00040 -0.00279"/>
      <mass value="1.50000"/>
    </inertial>
    <visual name="base_link_.002">
      <origin rpy="0.00000 0.00000 0.00000" xyz="0.00000 0.00000 0.00000"/>
      <material name="Primary"/>
      <geometry>
        <mesh filename="../meshes/dae/base_link.004.dae" scale="1.00000 1.00000 1.00000"/>
      </geometry>
    </visual>
    <collision>
      <origin rpy="0.00000 0.00000 0.00000" xyz="0.00000 0.00000 -0.00279"/>
      <geometry>
        <mesh filename="../meshes/dae/base_link.004.dae" scale="1.00000 1.00000 1.00000"/>
      </geometry>
    </collision>
  </link>

  <!-- Front Right Links -->
  <link name="fr_link0.002">
    <inertial>
      <inertia ixx="0.00020" ixy="-0.00000" ixz="-0.00001" iyy="0.00118" iyz="0.00000" izz="0.00107"/>
      <origin rpy="0.00000 0.00000 0.00000" xyz="0.00111 0.00069 0.09481"/>
      <mass value="0.40000"/>
    </inertial>
    <visual name="fr_llink0_.002">
      <origin rpy="-0.00000 1.57080 0.00000" xyz="0.00000 0.00000 -0.00000"/>
      <material name="Primary"/>
      <geometry>
        <mesh filename="../meshes/dae/fr_link_0.009.dae" scale="1.00000 1.00000 1.00000"/>
      </geometry>
    </visual>
  </link>

  <link name="fr_llink1.002">
    <inertial>
      <inertia ixx="0.00012" ixy="0.00000" ixz="0.00007" iyy="0.00016" iyz="-0.00001" izz="0.00005"/>
      <origin rpy="0.00000 0.00000 0.00000" xyz="0.01519 -0.02472 0.00644"/>
      <mass value="0.20000"/>
    </inertial>
    <visual name="fr_llink1_.002">
      <origin rpy="-1.57080 -0.00000 -0.00000" xyz="0.00000 0.00000 -0.00000"/>
      <material name="Grey"/>
      <geometry>
        <mesh filename="../meshes/dae/fr_link1.002.dae" scale="1.00000 1.00000 1.00000"/>
      </geometry>
    </visual>
  </link>

  <link name="fr_llink2.002">
    <inertial>
      <inertia ixx="0.00062" ixy="0.00006" ixz="-0.00045" iyy="0.00095" iyz="0.00008" izz="0.00036"/>
      <origin rpy="0.00000 0.00000 0.00000" xyz="-0.05980 -0.08004 -0.00440"/>
      <mass value="0.20000"/>
    </inertial>
    <visual name="fr_llink2_.002">
      <origin rpy="-1.57080 -0.00000 -0.00000" xyz="-0.00000 0.00000 -0.00000"/>
      <material name="Grey"/>
      <geometry>
        <mesh filename="../meshes/dae/fr_link2.002.dae" scale="1.00000 1.00000 1.00000"/>
      </geometry>
    </visual>
  </link>

  <link name="fr_llink3.002">
    <inertial>
      <inertia ixx="0.00012" ixy="-0.00000" ixz="0.00015" iyy="0.00031" iyz="0.00000" izz="0.00020"/>
      <origin rpy="0.00000 0.00000 0.00000" xyz="-0.05213 0.03967 0.00027"/>
      <mass value="0.20000"/>
    </inertial>
    <visual name="fr_llink3_.002">
      <origin rpy="-1.57080 -0.00000 -0.00000" xyz="0.00000 -0.00000 0.00000"/>
      <material name="Grey"/>
      <geometry>
        <mesh filename="../meshes/dae/fr_link3.002.dae" scale="1.00000 1.00000 1.00000"/>
      </geometry>
    </visual>
  </link>

  <link name="fr_llink4.002">
    <inertial>
      <inertia ixx="0.00012" ixy="-0.00000" ixz="-0.00006" iyy="0.00016" iyz="-0.00001" izz="0.00005"/>
      <origin rpy="0.00000 0.00000 0.00000" xyz="0.02541 0.04436 -0.00125"/>
      <mass value="0.20000"/>
    </inertial>
    <visual name="fr_llink4_.002">
      <origin rpy="-1.57080 -0.00000 -0.00000" xyz="0.03966 0.06964 -0.00768"/>
      <material name="Grey"/>
      <geometry>
        <mesh filename="../meshes/dae/fr_llink4.002.dae" scale="1.00000 1.00000 1.00000"/>
      </geometry>
    </visual>
  </link>

  <link name="link0.002">
    <inertial>
      <inertia ixx="0.00020" ixy="0.00000" ixz="0.00001" iyy="0.00118" iyz="0.00000" izz="0.00107"/>
      <origin rpy="0.00000 0.00000 0.00000" xyz="-0.00032 0.00122 0.09509"/>
      <mass value="0.40000"/>
    </inertial>
    <visual name="link0_.001">
      <origin rpy="-0.00000 -1.57080 0.00000" xyz="-0.00000 0.00000 -0.00000"/>
      <material name="Primary"/>
      <geometry>
        <mesh filename="../meshes/dae/fr_link_0.010.dae" scale="1.00000 1.00000 1.00000"/>
      </geometry>
    </visual>
  </link>

  <link name="link0.003">
    <inertial>
      <inertia ixx="0.00020" ixy="-0.00000" ixz="0.00001" iyy="0.00118" iyz="-0.00000" izz="0.00107"/>
      <origin rpy="0.00000 0.00000 0.00000" xyz="-0.00032 -0.00122 0.09509"/>
      <mass value="0.40000"/>
    </inertial>
    <visual name="link0_.002">
      <origin rpy="-0.00000 -1.57080 0.00000" xyz="-0.00000 -0.00000 -0.00000"/>
      <material name="Primary"/>
      <geometry>
        <mesh filename="../meshes/dae/fr_link_0.011.dae" scale="1.00000 1.00000 1.00000"/>
      </geometry>
    </visual>
  </link>

  <link name="link0.004">
    <inertial>
      <inertia ixx="0.00020" ixy="0.00000" ixz="-0.00001" iyy="0.00118" iyz="-0.00000" izz="0.00107"/>
      <origin rpy="0.00000 0.00000 0.00000" xyz="0.00032 -0.00122 0.09481"/>
      <mass value="0.40000"/>
    </inertial>
    <visual name="link0_.003">
      <origin rpy="-0.00000 1.57080 0.00000" xyz="-0.00000 -0.00000 0.00000"/>
      <material name="Primary"/>
      <geometry>
        <mesh filename="../meshes/dae/fr_link_0.012.dae" scale="1.00000 1.00000 1.00000"/>
      </geometry>
    </visual>
  </link>

  <link name="link1.002">
    <inertial>
      <inertia ixx="0.00012" ixy="-0.00000" ixz="-0.00007" iyy="0.00016" iyz="-0.00001" izz="0.00005"/>
      <origin rpy="0.00000 0.00000 0.00000" xyz="-0.01519 -0.02472 0.00644"/>
      <mass value="0.20000"/>
    </inertial>
    <visual name="link1_.001">
      <origin rpy="-1.57080 0.00000 -0.00000" xyz="0.00000 -0.00000 -0.00000"/>
      <material name="Grey"/>
      <geometry>
        <mesh filename="../meshes/dae/fr_link_1.008.dae" scale="1.00000 1.00000 1.00000"/>
      </geometry>
    </visual>
  </link>

  <link name="link1.003">
    <inertial>
      <inertia ixx="0.00012" ixy="0.00000" ixz="-0.00007" iyy="0.00016" iyz="0.00001" izz="0.00005"/>
      <origin rpy="0.00000 0.00000 0.00000" xyz="-0.01519 0.02472 0.00644"/>
      <mass value="0.20000"/>
    </inertial>
    <visual name="link1_.002">
      <origin rpy="1.57080 0.00000 -0.00000" xyz="0.00000 0.00000 -0.00000"/>
      <material name="Grey"/>
      <geometry>
        <mesh filename="../meshes/dae/fr_link_1.009.dae" scale="1.00000 1.00000 1.00000"/>
      </geometry>
    </visual>
  </link>

  <link name="link1.004">
    <inertial>
      <inertia ixx="0.00012" ixy="-0.00000" ixz="0.00007" iyy="0.00016" iyz="0.00001" izz="0.00005"/>
      <origin rpy="0.00000 0.00000 0.00000" xyz="0.01519 0.02472 0.00644"/>
      <mass value="0.20000"/>
    </inertial>
    <visual name="link1_.003">
      <origin rpy="1.57080 -0.00000 -0.00000" xyz="0.00000 0.00000 -0.00000"/>
      <material name="Grey"/>
      <geometry>
        <mesh filename="../meshes/dae/fr_link_1.010.dae" scale="1.00000 1.00000 1.00000"/>
      </geometry>
    </visual>
  </link>

  <link name="link2.002">
    <inertial>
      <inertia ixx="0.00062" ixy="-0.00006" ixz="0.00045" iyy="0.00095" iyz="0.00008" izz="0.00036"/>
      <origin rpy="0.00000 0.00000 0.00000" xyz="0.05973 -0.08000 -0.00430"/>
      <mass value="0.20000"/>
    </inertial>
    <visual name="link2_.001">
      <origin rpy="-1.57080 -0.00000 0.00000" xyz="0.00000 -0.00000 -0.00000"/>
      <material name="Grey"/>
      <geometry>
        <mesh filename="../meshes/dae/fr_link_2.008.dae" scale="1.00000 1.00000 1.00000"/>
      </geometry>
    </visual>
  </link>

  <link name="link2.003">
    <inertial>
      <inertia ixx="0.00062" ixy="0.00006" ixz="0.00045" iyy="0.00095" iyz="-0.00008" izz="0.00036"/>
      <origin rpy="0.00000 0.00000 0.00000" xyz="0.05980 0.08004 -0.00440"/>
      <mass value="0.20000"/>
    </inertial>
    <visual name="link2_.002">
      <origin rpy="1.57080 0.00000 -0.00000" xyz="-0.00000 0.00000 0.00000"/>
      <material name="Grey"/>
      <geometry>
        <mesh filename="../meshes/dae/fr_link_2.009.dae" scale="1.00000 1.00000 1.00000"/>
      </geometry>
    </visual>
  </link>

  <link name="link2.004">
    <inertial>
      <inertia ixx="0.00062" ixy="-0.00006" ixz="-0.00045" iyy="0.00095" iyz="-0.00008" izz="0.00036"/>
      <origin rpy="0.00000 0.00000 0.00000" xyz="-0.05973 0.08000 -0.00430"/>
      <mass value="0.20000"/>
    </inertial>
    <visual name="link2_.003">
      <origin rpy="1.57080 0.00000 0.00000" xyz="-0.00000 0.00000 0.00000"/>
      <material name="Grey"/>
      <geometry>
        <mesh filename="../meshes/dae/fr_link_2.010.dae" scale="1.00000 1.00000 1.00000"/>
      </geometry>
    </visual>
  </link>

  <link name="link3.002">
    <inertial>
      <inertia ixx="0.00012" ixy="0.00000" ixz="-0.00015" iyy="0.00031" iyz="0.00000" izz="0.00020"/>
      <origin rpy="0.00000 0.00000 0.00000" xyz="0.05213 0.03967 0.00027"/>
      <mass value="0.20000"/>
    </inertial>
    <visual name="link3_.001">
      <origin rpy="-1.57080 -0.00000 0.00000" xyz="0.00000 0.00000 0.00000"/>
      <material name="Grey"/>
      <geometry>
        <mesh filename="../meshes/dae/fr_link_3.008.dae" scale="1.00000 1.00000 1.00000"/>
      </geometry>
    </visual>
  </link>
  
  <link name="link3.003">
    <inertial>
      <inertia ixx="0.00012" ixy="-0.00000" ixz="-0.00015" iyy="0.00031" iyz="-0.00000" izz="0.00020"/>
      <origin rpy="0.00000 0.00000 0.00000" xyz="0.05213 -0.03967 0.00027"/>
      <mass value="0.20000"/>
    </inertial>
    <visual name="link3_.002">
      <origin rpy="1.57080 -0.00000 0.00000" xyz="0.00000 -0.00000 -0.00000"/>
      <material name="Grey"/>
      <geometry>
        <mesh filename="../meshes/dae/fr_link_3.009.dae" scale="1.00000 1.00000 1.00000"/>
      </geometry>
    </visual>
  </link>

  <link name="link3.004">
    <inertial>
      <inertia ixx="0.00012" ixy="0.00000" ixz="0.00015" iyy="0.00031" iyz="-0.00000" izz="0.00020"/>
      <origin rpy="0.00000 0.00000 0.00000" xyz="-0.05213 -0.03967 0.00027"/>
      <mass value="0.20000"/>
    </inertial>
    <visual name="link3_.003">
      <origin rpy="1.57080 -0.00000 0.00000" xyz="-0.00000 -0.00000 -0.00000"/>
      <material name="Grey"/>
      <geometry>
        <mesh filename="../meshes/dae/fr_link_3.010.dae" scale="1.00000 1.00000 1.00000"/>
      </geometry>
    </visual>
  </link>

  <link name="link4.001">
    <inertial>
      <inertia ixx="0.00012" ixy="0.00000" ixz="0.00006" iyy="0.00016" iyz="-0.00001" izz="0.00005"/>
      <origin rpy="0.00000 0.00000 0.00000" xyz="-0.02541 0.04436 -0.00125"/>
      <mass value="0.20000"/>
    </inertial>
    <visual name="link4_.001">
      <origin rpy="-1.57080 -0.00000 0.00000" xyz="-0.03957 0.06951 -0.00768"/>
      <material name="Grey"/>
      <geometry>
        <mesh filename="../meshes/dae/link4.008.dae" scale="1.00000 1.00000 1.00000"/>
      </geometry>
    </visual>
  </link>

  <link name="link4.004">
    <inertial>
      <inertia ixx="0.00012" ixy="-0.00000" ixz="0.00006" iyy="0.00016" iyz="0.00001" izz="0.00005"/>
      <origin rpy="0.00000 0.00000 0.00000" xyz="-0.02534 -0.04440 -0.00134"/>
      <mass value="0.20000"/>
    </inertial>
    <visual name="link4_.002">
      <origin rpy="1.57080 -0.00000 0.00000" xyz="-0.03950 -0.06955 -0.00778"/>
      <material name="Grey"/>
      <geometry>
        <mesh filename="../meshes/dae/link4.009.dae" scale="1.00000 1.00000 1.00000"/>
      </geometry>
    </visual>
  </link>

  <link name="link4.005">
    <inertial>
      <inertia ixx="0.00012" ixy="0.00000" ixz="-0.00006" iyy="0.00016" iyz="0.00001" izz="0.00005"/>
      <origin rpy="0.00000 0.00000 0.00000" xyz="0.02534 -0.04440 -0.00134"/>
      <mass value="0.20000"/>
    </inertial>
    <visual name="link4_.003">
      <origin rpy="1.57080 -0.00000 -0.00000" xyz="0.03950 -0.06955 -0.00778"/>
      <material name="Grey"/>
      <geometry>
        <mesh filename="../meshes/dae/link4.010.dae" scale="1.00000 1.00000 1.00000"/>
      </geometry>
    </visual>
  </link>

  <material name="Grey">
    <color rgba="0.39608 0.47059 0.54510 1.00000"/>
  </material>
  <material name="Primary">
    <color rgba="0.92941 0.56471 0.36471 1.00000"/>
  </material>
</robot>