<!-- <?xml version="1.0" encoding="utf-8"?> -->
<!-- This URDF was automatically created by SolidWorks to URDF Exporter! Originally created by Stephen Brawner (brawner@gmail.com) 
     Commit Version: 1.6.0-4-g7f85cfe  Build Version: 1.6.7995.38578
     For more information, please see http://wiki.ros.org/sw_urdf_exporter -->
<robot
  name="quadbot">
  <link
    name="base_link">
    <inertial>
      <origin
        xyz="0.015391 0.18702 -1.9815E-06"
        rpy="0 0 0" />
      <mass
        value="1.1069" />
      <inertia
        ixx="0.0039434"
        ixy="-2.2459E-12"
        ixz="2.0626E-09"
        iyy="0.0047314"
        iyz="-1.5796E-06"
        izz="0.0039285" />
    </inertial>
    <visual>
      <origin
        xyz="0 0 0"
        rpy="0 0 0" />
      <geometry>
        <mesh
          filename="../meshes/base_link.STL" />
      </geometry>
      <material
        name="">
        <color
          rgba="1 0.67059 0.87059 1" />
      </material>
    </visual>
    <collision>
      <origin
        xyz="0 0 0"
        rpy="0 0 0" />
      <geometry>
        <mesh
          filename="../meshes/base_link.STL" />
      </geometry>
    </collision>
  </link>
  <link
    name="FR_link">
    <inertial>
      <origin
        xyz="-1.9871E-05 0.013716 -0.050139"
        rpy="0 0 0" />
      <mass
        value="0.11038" />
      <inertia
        ixx="0.00011182"
        ixy="2.0626E-09"
        ixz="-1.7773E-06"
        iyy="0.0001567"
        iyz="-2.2451E-12"
        izz="5.3382E-05" />
    </inertial>
    <visual>
      <origin
        xyz="0 0 0"
        rpy="0 0 0" />
      <geometry>
        <mesh
          filename="../meshes/FR_link.STL" />
      </geometry>
      <material
        name="">
        <color
          rgba="0.79216 0.79216 0.79216 1" />
      </material>
    </visual>
    <collision>
      <origin
        xyz="0 0 0"
        rpy="0 0 0" />
      <geometry>
        <mesh
          filename="../meshes/FR_link.STL" />
      </geometry>
    </collision>
  </link>
  <joint
    name="FR_joint"
    type="revolute">
    <origin
      xyz="0.068396 -0.079 0.19165"
      rpy="-1.5708 1.564 1.5708" />
    <parent
      link="base_link" />
    <child
      link="FR_link" />
    <axis
      xyz="0 0 1" />
    <limit
      lower="0"
      upper="3.14"
      effort="0"
      velocity="0" />
  </joint>
  <link
    name="FR_1_link">
    <inertial>
      <origin
        xyz="0.0291578714898912 -0.00987962579279213 -1.12132525487141E-14"
        rpy="0 0 0" />
      <mass
        value="0.0209412067295075" />
      <inertia
        ixx="9.42722406410459E-07"
        ixy="1.54265002106538E-07"
        ixz="2.2356624005777E-21"
        iyy="1.22072933903446E-05"
        iyz="-2.24993126614424E-22"
        izz="1.14710057680368E-05" />
    </inertial>
    <visual>
      <origin
        xyz="0 0 0"
        rpy="0 0 0" />
      <geometry>
        <mesh
          filename="../meshes/FR_1_link.STL" />
      </geometry>
      <material
        name="">
        <color
          rgba="0.627450980392157 0.627450980392157 0.627450980392157 1" />
      </material>
    </visual>
    <collision>
      <origin
        xyz="0 0 0"
        rpy="0 0 0" />
      <geometry>
        <mesh
          filename="../meshes/FR_1_link.STL" />
      </geometry>
    </collision>
  </link>
  <joint
    name="FR_1_joint"
    type="revolute">
    <origin
      xyz="0 0.031751 -0.082"
      rpy="3.1416 0.97613 0" />
    <parent
      link="FR_link" />
    <child
      link="FR_1_link" />
    <axis
      xyz="0 1 0" />
    <limit
      lower="0"
      upper="3.14"
      effort="0"
      velocity="0" />
  </joint>
  <link
    name="FR_2_link">
    <inertial>
      <origin
        xyz="-0.000248700730455437 -0.100976764101735 -0.00648758022394789"
        rpy="0 0 0" />
      <mass
        value="0.0364575799194722" />
      <inertia
        ixx="5.58581169249248E-05"
        ixy="5.66699347727094E-08"
        ixz="4.43522719988858E-11"
        iyy="9.04626145158037E-07"
        iyz="1.08482409824532E-08"
        izz="5.64901840947864E-05" />
    </inertial>
    <visual>
      <origin
        xyz="0 0 0"
        rpy="0 0 0" />
      <geometry>
        <mesh
          filename="../meshes/FR_2_link.STL" />
      </geometry>
      <material
        name="">
        <color
          rgba="0.627450980392157 0.627450980392157 0.627450980392157 1" />
      </material>
    </visual>
    <collision>
      <origin
        xyz="0 0 0"
        rpy="0 0 0" />
      <geometry>
        <mesh
          filename="../meshes/FR_2_link.STL" />
      </geometry>
    </collision>
  </link>
  <joint
    name="FR_2_joint"
    type="revolute">
    <origin
      xyz="0.08 0 0"
      rpy="1.5708 0.35633 3.1416" />
    <parent
      link="FR_1_link" />
    <child
      link="FR_2_link" />
    <axis
      xyz="0 0 1" />
    <limit
      lower="0"
      upper="3.14"
      effort="0"
      velocity="0" />
  </joint>
  <link
    name="FR_3_link">
    <inertial>
      <origin
        xyz="0.000136237888330254 0.0658007969173274 0.00599999999999996"
        rpy="0 0 0" />
      <mass
        value="0.0221842987960633" />
      <inertia
        ixx="2.81354775768645E-05"
        ixy="-1.46900586685661E-07"
        ixz="4.89690922631392E-22"
        iyy="5.34735340581066E-07"
        iyz="2.15827965427336E-20"
        izz="2.85375296980227E-05" />
    </inertial>
    <visual>
      <origin
        xyz="0 0 0"
        rpy="0 0 0" />
      <geometry>
        <mesh
          filename="../meshes/FR_3_link.STL" />
      </geometry>
      <material
        name="">
        <color
          rgba="0.627450980392157 0.627450980392157 0.627450980392157 1" />
      </material>
    </visual>
    <collision>
      <origin
        xyz="0 0 0"
        rpy="0 0 0" />
      <geometry>
        <mesh
          filename="../meshes/FR_3_link.STL" />
      </geometry>
    </collision>
  </link>
  <joint
    name="FR_3_joint"
    type="revolute">
    <origin
      xyz="0 -0.1 -0.016499"
      rpy="0 0 -1.3056" />
    <parent
      link="FR_2_link" />
    <child
      link="FR_3_link" />
    <axis
      xyz="0 0 1" />
    <limit
      lower="0"
      upper="3.14"
      effort="0"
      velocity="0" />
  </joint>
  <link
    name="FR_4_link">
    <inertial>
      <origin
        xyz="0.029158 0.0066196 2.0151E-14"
        rpy="0 0 0" />
      <mass
        value="0.020941" />
      <inertia
        ixx="9.4272E-07"
        ixy="1.5427E-07"
        ixz="1.597E-21"
        iyy="1.2207E-05"
        iyz="-1.8198E-22"
        izz="1.1471E-05" />
    </inertial>
    <visual>
      <origin
        xyz="0 0 0"
        rpy="0 0 0" />
      <geometry>
        <mesh
          filename="../meshes/FR_4_link.STL" />
      </geometry>
      <material
        name="">
        <color
          rgba="0.62745 0.62745 0.62745 1" />
      </material>
    </visual>
    <collision>
      <origin
        xyz="0 0 0"
        rpy="0 0 0" />
      <geometry>
        <mesh
          filename="../meshes/FR_4_link.STL" />
      </geometry>
    </collision>
  </link>
  <joint
    name="FR_4_joint"
    type="revolute">
    <origin
      xyz="-0.064226 0.1777 0"
      rpy="1.5708 0 -0.63878" />
    <parent
      link="FR_3_link" />
    <child
      link="FR_4_link" />
    <axis
      xyz="0 0.0068294 -0.99998" />
    <limit
      lower="0"
      upper="3.14"
      effort="0"
      velocity="0" />
  </joint>
  <!-- <link
    name="Empty_Link">
    <inertial>
      <origin
        xyz="0 0 0"
        rpy="0 0 0" />
      <mass
        value="0" />
      <inertia
        ixx="0"
        ixy="0"
        ixz="0"
        iyy="0"
        iyz="0"
        izz="0" />
    </inertial>
    <visual>
      <origin
        xyz="0 0 0"
        rpy="0 0 0" />
      <geometry>
        <mesh
          filename="../meshes/Empty_Link.STL" />
      </geometry>
      <material
        name="">
        <color
          rgba="1 1 1 1" />
      </material>
    </visual>
    <collision>
      <origin
        xyz="0 0 0"
        rpy="0 0 0" />
      <geometry>
        <mesh
          filename="../meshes/Empty_Link.STL" />
      </geometry>
    </collision>
  </link> -->
  <!-- <joint
    name="tmp_joint"
    type="revolute">
    <origin
      xyz="0 0 0"
      rpy="0 0 0" />
    <parent
      link="" />
    <child
      link="" />
    <axis
      xyz="0 -1 0" />
    <limit
      lower="0"
      upper="3.14"
      effort="0"
      velocity="0" />
  </joint> -->
</robot>